Workbook
Name B_IMAGEN: INDEX(IMAGEN,MATCH('IMAG MOD 25-26'!$D$2,CAMION,0))
Name B_IMAGEN2: INDEX(IMAGEN,MATCH('COTIZADOR X2'!$J$24,CAMION,0))
Name CAMION: 'IMAG MOD 25-26'!$A$2:$A$44
Name IMAGEN: 'IMAG MOD 25-26'!$B$2:$B$59
Name MODELO: 'IMAG MOD 25-26'!#REF!

Sheet DATOS1
A1: CATALOGO | B1: AÑO MODELO | C1: AÑO MODELO | D1: PRECIO 2025 | E1: PRECIO 2026
A2: ELF 100E | B2: 2025 | C2: 2026 | D2: 719700 | E2: 808700 | F2: =A2&B2 -> ELF 100E2025
A3: ELF 200E | B3: 2025 | C3: 2026 | D3: 889900 | E3: 986200
A4: ELF 300E | B4: 2025 | C4: 2026 | D4: 987900 | E4: 1088500
A5: ELF 300H | B5: 2025 | C5: 2026 | D5: 1006400 | E5: 1107800
A6: ELF 350F | B6: 2025 | C6: 2026 | D6: 0 | E6: 1165700
A7: ELF 350H | B7: 2025 | C7: 2026 | D7: 0 | E7: 1188900
A8: ELF 350K | B8: 2025 | C8: 2026 | D8: 0 | E8: 1204300
A9: ELF 400F | B9: 2025 | C9: 2026 | D9: 1098900 | E9: 1223600
A10: ELF 400H | B10: 2025 | C10: 2026 | D10: 1121100 | E10: 1246800
A11: ELF 400K | B11: 2025 | C11: 2026 | D11: 1135900 | E11: 1262200
A12: ELF 500F | B12: 2025 | C12: 2026 | D12: 1187700 | E12: 1316300
A13: ELF 500H | B13: 2025 | C13: 2026 | D13: 1198800 | E13: 1327800
A14: ELF 500K | B14: 2025 | C14: 2026 | D14: 1219200 | E14: 1349100
... A21: FORWARD 1100L | B21: 2025 | C21: 2026 | D21: 1694600 | E21: 1825800
A22: FORWARD 1100M | C22: 2026 | D22: 0 | E22: 0
A23: FORWARD 1100Q | B23: 2025 | C23: 2026 | D23: 1716800 | E23: 1848900
A24: FORWARD 1400K | B24: 2025 | C24: 2026 | D24: 1792700 | E24: 1928100
A25: FORWARD 1400M | C25: 2026 | D25: 0 | E25: 0
A26: FORWARD 1400Q | B26: 2025 | C26: 2026 | D26: 1826000 | E26: 1962800

Sheet DATOS 2
A1: MODELO | B1: AÑO MODELO | C1: PRECIO | D1: CAPACIDAD DE CARGA | E1: LARGO CHASIS | F1: ALTO CAMIÓN | G1: ANCHO CABINA | H1: LARGO APLICACIÓN | I1: ALTO APLICACIÓN | J1: ANCHO APLICACIÓN | K1: DISTANCIA ENTRE EJES | L1: PVB | M1: MOTOR | N1: TECNOLOGIA | O1: GARANTIA | P1: EQUIPO | Q1: FRENOS | R1: HP | S1: ib-pie @ rpm | T1: Km/L | U1: FAMILIA | V1: NOMENCLATURA | W1: LLANTAS
A2: ELF 100E | B2: 2026 | C2: 766800 | D2: 1.8 T | E2: 4.73 | F2: 2.23 | G2: 1.815 | H2: 3.3 | I2: 2 | J2: 2 | K2: 2.475 | L2: 3.9 | M2: 4 cilindros 2,999 CC DOHC+VVT / TURBO VGS + EGR + DPD + SCR | N2: EURO VI | O2: 3 años o 100,000 kms | P2: BOLSAS DE AIRE y PANTALLA DIGITAL EN TABLERO con 21 FUNCIONES + CÁMARA DE REVERSA + AIRE ACONDICIONADO + STAR ASSIST | Q2: VAC-TAMBOR / TAMBOR VÁLVULA LSPV | R2: 148 @ 2800 | S2: 277 @ 1,280 | T2: 11 KM/LT | U2: ELF | V2: 100 | W2: 205 / 75 R16C - 113 / 111
A3: ELF 200E | B3: 2026 | C3: 935100 | D3: 2.6 T | E3: 4.73 | F3: 2.23 | G3: 1.815 | H3: 3.3 | I3: 2 | J3: 2 | K3: 2.475 | L3: 4.1 | M3: 4 cilindros 2,999 CC DOHC+VVT / TURBO VGS + EGR + DPD + SCR | N3: EURO VI | O3: 3 años o 100,000 kms | P3: BOLSAS DE AIRE y PANTALLA DIGITAL EN TABLERO con 21 FUNCIONES + CÁMARA DE REVERSA + AIRE ACONDICIONADO + STAR ASSIST | Q3: VAC-TAMBOR/TAMBOR VÁLVULA LSPV | R3: 148 @ 2800 | S3: 277 @ 1,280 | T3: 10 KM/LT | U3: ELF | V3: 200 | W3: 205 / 75 R16C - 113 / 111
A4: ELF 300E | B4: 2026 | C4: 1032100 | D4: 3.5 T | E4: 4.725 | F4: 2.262 | G4: 1.815 | H4: 3.3 | I4: 2 | J4: 2 | K4: 2.475 | L4: 5 | M4: 4 cilindros 2,999 CC DOHC+VVT / TURBO VGS + EGR + DPD + SCR | N4: EURO VI | O4: 3 años o 100,000 kms | P4: BOLSAS DE AIRE y PANTALLA DIGITAL EN TABLERO con 21 FUNCIONES + CÁMARA DE REVERSA + AIRE ACONDICIONADO + STAR ASSIST | Q4: VAC-DISCO/TAMBOR ABS+EBD | R4: 148 @ 2800 | S4: 277 @ 1,280 | T4: 9 KM/LT | U4: ELF | V4: 300 | W4: 205 / 75 R16C - 113 / 111
A5: ELF 300H | B5: 2026 | C5: 1050400 | D5: 3.5 T | E5: 6.02 | F5: 2.262 | G5: 1.815 | H5: 4.5 | I5: 2 | J5: 2 | K5: 3.345 | L5: 5 | M5: 4 cilindros 2,999 CC DOHC+VVT / TURBO VGS + EGR + DPD + SCR | N5: EURO VI | O5: 3 años o 100,000 kms | P5: BOLSAS DE AIRE y PANTALLA DIGITAL EN TABLERO con 21 FUNCIONES + CÁMARA DE REVERSA + AIRE ACONDICIONADO + STAR ASSIST | Q5: VAC-DISCO/TAMBOR ABS+EBD | R5: 148 @ 2800 | S5: 277 @ 1,280 | T5: 9 KM/LT | U5: ELF | V5: 300 | W5: 205 / 75 R16C - 113 / 111
A6: ELF 350F | B6: 2026 | C6: 1105300 | D6: 4 T | E6: 5.135 | F6: 2.26 | G6: 2.04 | H6: 3.8 | I6: 2.2 | J6: 2.4 | K6: 2.765 | L6: 5.8 | M6: 4 cilindros 2,999 CC DOHC+VVT / TURBO VGS + EGR + DOC + DPD + SCR | N6: EURO VI | O6: 3 años o 100,000 kms | P6: BOLSAS DE AIRE y PANTALLA DIGITAL EN TABLERO con 21 FUNCIONES + CÁMARA DE REVERSA + AIRE ACONDICIONADO + STAR ASSIST | Q6: VAC-DISCO/TAMBOR ABS+EBD+BOOST ASSIST | R6: 148 @ 2800 | S6: 277 @ 1,280 | T6: 8.5 KM/LT | U6: ELF | V6: 350 | W6: 215 / 85 R16 - 10 PR
A7: ELF 350H | B7: 2026 | C7: 1127300 | D7: 4 T | E7: 5.985 | F7: 2.26 | G7: 2.04 | H7: 4.6 | I7: 2.2 | J7: 2.4 | K7: 3.365 | L7: 5.8 | M7: 4 cilindros 2,999 CC DOHC+VVT / TURBO VGS + EGR + DOC + DPD + SCR | N7: EURO VI | O7: 3 años o 100,000 kms | P7: BOLSAS DE AIRE y PANTALLA DIGITAL EN TABLERO con 21 FUNCIONES + CÁMARA DE REVERSA + AIRE ACONDICIONADO + STAR ASSIST | Q7: VAC-DISCO/TAMBOR ABS+EBD+BOOST ASSIST | R7: 148 @ 2800 | S7: 277 @ 1,280 | T7: 8.5 KM/LT | U7: ELF | V7: 350 | W7: 215 / 85 R16 - 10 PR
A8: ELF 350K | B8: 2026 | C8: 1141900 | D8: 4 T | E8: 6.635 | F8: 2.26 | G8: 2.04 | H8: 5.2 | I8: 2.2 | J8: 2.4 | K8: 3.815 | L8: 5.8 | M8: 4 cilindros 2,999 CC DOHC+VVT / TURBO VGS + EGR + DOC + DPD + SCR | N8: EURO VI | O8: 3 años o 100,000 kms | P8: BOLSAS DE AIRE y PANTALLA DIGITAL EN TABLERO con 21 FUNCIONES + CÁMARA DE REVERSA + AIRE ACONDICIONADO + STAR ASSIST | Q8: VAC-DISCO/TAMBOR ABS+EBD+BOOST ASSIST | R8: 148 @ 2800 | S8: 277 @ 1,280 | T8: 8.5 KM/LT | U8: ELF | V8: 350 | W8: 215 / 85 R16 - 10 PR
A9: ELF 400F | B9: 2026 | C9: 1160200 | D9: 4 T | E9: 5.135 | F9: 2.328 | G9: 2.04 | H9: 3.8 | I9: 2.2 | J9: 2.4 | K9: 2.76 | L9: 6.577 | M9: 4 cilindros 5,194 CC OHC / TURBO VGS + EGR + DPD + SCR | N9: EURO VI | O9: 3 años o 100,000 kms | P9: BOLSA DE AIRE CONDUCTOR + CÁMARA DE REVERSA +AIRE ACONDICIONADO + ALARMA DE REVERSA + MANDOS AL VOLANTE+ CIERRE CENTRALIZADO VENTANAS ELÉCTRICAS + PUERTO USB (SÓLO ENERGÍA) | Q9: VAC-DISCO/TAMBOR ABS+EBD+BOOST ASSIST | R9: 182 @ 2600 | S9: 372 @ 1600 | T9: 7 KM/LT | U9: ELF | V9: 400 | W9: 215 / 85 R16 - 10 PR
A10: ELF 400H | B10: 2026 | C10: 1182200 | D10: 4 T | E10: 5.985 | F10: 2.328 | G10: 2.04 | H10: 4.6 | I10: 2.2 | J10: 2.4 | K10: 3.36 | L10: 6.577 | M10: 4 cilindros 5,194 CC OHC / TURBO VGS + EGR + DPD + SCR | N10: EURO VI | O10: 3 años o 100,000 kms | P10: BOLSA DE AIRE CONDUCTOR + CÁMARA DE REVERSA +AIRE ACONDICIONADO + ALARMA DE REVERSA + MANDOS AL VOLANTE+ CIERRE CENTRALIZADO VENTANAS ELÉCTRICAS + PUERTO USB (SÓLO ENERGÍA) | Q10: VAC-DISCO/TAMBOR ABS+EBD+BOOST ASSIST | R10: 182 @ 2600 | S10: 372 @ 1600 | T10: 7 KM/LT | U10: ELF | V10: 400 | W10: 215 / 85 R16 - 10 PR
A11: ELF 400K | B11: 2026 | C11: 1196800 | D11: 4 T | E11: 6.635 | F11: 2.328 | G11: 2.04 | H11: 5.2 | I11: 2.2 | J11: 2.4 | K11: 3.8 | L11: 6.577 | M11: 4 cilindros 5,194 CC OHC / TURBO VGS + EGR + DPD + SCR | N11: EURO VI | O11: 3 años o 100,000 kms | P11: BOLSA DE AIRE CONDUCTOR + CÁMARA DE REVERSA +AIRE ACONDICIONADO + ALARMA DE REVERSA + MANDOS AL VOLANTE+ CIERRE CENTRALIZADO VENTANAS ELÉCTRICAS + PUERTO USB (SÓLO ENERGÍA) | Q11: VAC-DISCO/TAMBOR ABS+EBD+BOOST ASSIST | R11: 182 @ 2600 | S11: 372 @ 1600 | T11: 7 KM/LT | U11: ELF | V11: 400 | W11: 215 / 85 R16 - 10 PR
A12: ELF 500F | B12: 2026 | C12: 1248100 | D12: 5 T | E12: 5.135 | F12: 2.352 | G12: 2.04 | H12: 3.8 | I12: 2.2 | J12: 2.4 | K12: 2.76 | L12: 7.257 | M12: 4 cilindros 5,194 CC OHC / TURBO VGS + EGR + DPD + SCR | N12: EURO VI | O12: 3 años o 100,000 kms | P12: BOLSA DE AIRE CONDUCTOR + CÁMARA DE REVERSA +AIRE ACONDICIONADO + ALARMA DE REVERSA + MANDOS AL VOLANTE+ CIERRE CENTRALIZADO VENTANAS ELÉCTRICAS + PUERTO USB (SÓLO ENERGÍA) | Q12: VAC-DISCO/TAMBOR ABS+EBD+BOOST ASSIST | R12: 182 @ 2600 | S12: 372 @ 1600 | T12: 6 KM/LT | U12: ELF | V12: 500 | W12: 225 / 70 R19.5 - 12 PR
A13: ELF 500H | B13: 2026 | C13: 1259000 | D13: 5 T | E13: 5.985 | F13: 2.352 | G13: 2.04 | H13: 4.6 | I13: 2.2 | J13: 2.4 | K13: 3.36 | L13: 7.257 | M13: 4 cilindros 5,194 CC OHC / TURBO VGS + EGR + DPD + SCR | N13: EURO VI | O13: 3 años o 100,000 kms | P13: BOLSA DE AIRE CONDUCTOR + CÁMARA DE REVERSA +AIRE ACONDICIONADO + ALARMA DE REVERSA + MANDOS AL VOLANTE+ CIERRE CENTRALIZADO VENTANAS ELÉCTRICAS + PUERTO USB (SÓLO ENERGÍA) | Q13: VAC-DISCO/TAMBOR ABS+EBD+BOOST ASSIST | R13: 182 @ 2600 | S13: 372 @ 1600 | T13: 6 KM/LT | U13: ELF | V13: 500 | W13: 225 / 70 R19.5 - 12 PR
... A24: FORWARD 1400Q | B24: 2026 | C24: 1830600 | D24: 12 T | E24: 9.255 | F24: 2.75 | G24: 2.395 | H24: 7.5 | I24: 2.6 | J24: 2.6 | K24: 5.55 | L24: 17 | M24: 6 cilindros 7,790 CC OHC / TURBO VGS + EGR + DPD + SCR | N24: EURO VI | O24: 2 años SIN límite de kms | P24: BOLSA DE AIRE CONDUCTOR + CÁMARA DE REVERSA +AIRE ACONDICIONADO + ALARMA DE REVERSA + PANTALLA DE INFORMACIÓN MÚLTIPLE | Q24: FRENOS DE AIRE TAMBOR/TAMBOR + ABS | R24: 271 @ 2400 | S24: 724 @ 1450 | T24: 4.5 KM/LT | U24: FORWARD | V24: 1400 | W24: 11R22.5 148 / 145

Sheet COTIZADOR X2
A4: RAZÓN SOCIAL: | J4: Guadalajara Jal.
A5: Con Atención a: | J5: =TODAY() -> 46065
A6: PRESENTE
A7: Ponemos a su consideración la presente cotización de nuestras unidades, acorde a su solicitud de información y necesidad de carga:
A9: Catalogo | C9: Capacidad de Carga | E9: Dimensiones del Vehículo | I9: Dimensión de la Aplicación | J9: Distancia Entre Ejes | K9: Peso Bruto Vehicular | L9: Precio Modelo
L10: =VLOOKUP(A13,'DATOS 2'!A:V,2,0) -> 2026
A12: Isuzu | C12: TONS | E12: MTS | I12: MTS | J12: MTS | K12: TONS | L12: MXN$
A13: ELF 100E | C13: =VLOOKUP(A13,'DATOS 2'!A:V,4,0) -> 1.8 T | E13: Largo | G13: =VLOOKUP(A13,'DATOS 2'!A:V,5,0) -> 4.73 | I13: =VLOOKUP(A13,'DATOS 2'!A:V,8,0) -> 3.3 | J13: =VLOOKUP(A13,'DATOS 2'!A:V,11,0) -> 2.475 | K13: =VLOOKUP(A13,'DATOS 2'!A:V,12,0) -> 3.9 | L13: =VLOOKUP(A13,'DATOS 2'!A:V,3,0)+12000 -> 778800
E14: Alto | G14: =VLOOKUP(A13,'DATOS 2'!A:V,6,0) -> 2.23 | I14: =VLOOKUP(A13,'DATOS 2'!A:V,9,0) -> 2
E15: Ancho | G15: =VLOOKUP(A13,'DATOS 2'!A:V,7,0) -> 1.815 | I15: =VLOOKUP(A13,'DATOS 2'!A:V,10,0) -> 2
A17: Caja Seca - Piso de Lámina Antiderrapante, Un Nivel de Riel Logístico, Zóclo & Puertas tipo Tráiler | G17: MT3 | I17: =(I18-0.2)*(I19-0.2)*(I20-0.15) -> 10.323 | J17: Descuento Especial
G18: Largo Ext: | I18: =VLOOKUP(A13,'DATOS 2'!A:V,8,0) -> 3.3 | J18: Unidad en Existencia, Entrega Inmediata Chasis Cabina* | L18: 0
G19: Alto Ext: | I19: =VLOOKUP(A13,'DATOS 2'!A:V,9,0) -> 2
G20: Ancho Ext: | I20: =VLOOKUP(A13,'DATOS 2'!A:V,10,0) -> 2
A22: GRAN TOTAL | L22: =L13+L18 -> 778800
A24: ISUZU | G24: =VLOOKUP(A13,'DATOS 2'!A:V,22,0) -> 100 | I24: =VLOOKUP(A13,'DATOS 2'!A:V,4,0) -> 1.8 T | J24: =$A$13 -> ELF 100E
A25: =VLOOKUP(A13,'DATOS 2'!A:V,21,0) -> ELF | G25: =VLOOKUP(A13,'DATOS 2'!A:V,20,0) -> 11 KM/LT | I25: TONS/CARGA
A27: Largo Máximo de Aplicación | C27: =VLOOKUP(A13,'DATOS 2'!A:V,8,0) -> 3.3 | E27: LLANTAS | G27: =VLOOKUP(A13,'DATOS 2'!A:W,23,0) -> 205 / 75 R16C - 113 / 111
A29: Motor | C29: =VLOOKUP(A13,'DATOS 2'!A:V,13,0) -> 4 cilindros 2,999 CC DOHC+VVT / TURBO VGS + EGR + DPD + SCR
A31: Tecnología | C31: =VLOOKUP(A13,'DATOS 2'!A:V,14,0) -> EURO VI | E31: FRENOS | G31: =VLOOKUP(A13,'DATOS 2'!A:V,17,0) -> VAC-TAMBOR / TAMBOR VÁLVULA LSPV
A33: Potencia | C33: hp | D33: =VLOOKUP(A13,'DATOS 2'!A:V,18,0) -> 148 @ 2800 | G33: ib-pie@rpm | I33: =VLOOKUP(A13,'DATOS 2'!A:V,19,0) -> 277 @ 1,280
A35: Garantía | C35: =VLOOKUP(A13,'DATOS 2'!A:V,15,0) -> 3 años o 100,000 kms
A37: Equipo | C37: =VLOOKUP(A13,'DATOS 2'!A:V,16,0) -> BOLSAS DE AIRE y PANTALLA DIGITAL EN TABLERO con 21 FUNCIONES + CÁMARA DE REVERSA + AIRE ACONDICIONADO + STAR ASSIST
A40: Cotización Vigente Hasta el 28 de Febrero de 2026
A42: · Precios Incluyen IVA.
A43: · Imagen Ilustrativa. La unidad No incluye el Equipo Aliado.
A44: · * UNIDAD SUJETA A DISPONIBILIDAD.
A45: · Límite del T.C. $ 20.00 MXN/USD. Precios sujetos a cambios sin previo aviso.
A46: · La Unidad viene con A/C y Cámara de Reversa Instalados, en el Camión.
A47: · Se anexa Ficha Técnica de la unidad.
A48: · Esta información se envía en formato digital a: | H48: Clienteee@gmail.com
A50: Agradezco su atención y quedo atento a sus comentarios y/o sugerencias.
A52: ATENTAMENTE
E53: Julián Álvarez González
A54: Asesor Comercial
A55: Cel: (33) – 1926 – 9780
A56: Ofi: (33) – 1646 – 0146
A57: jalvarez@isuzucamiones.com
A59: PLASENCIA CAMIONES DE GUADALAJARA S.A. DE C.V.
E60: SUC. ABASTOS
...

Sheet IMAGEN MOD

Sheet IMAG MOD 25-26
A1: CAMION | B1: IMAGEN | D1: CAMION | E1: IMAGEN
A2: ELF 100E. | D2: FWD 1400 26
A3: ELF 100E
A4: ELF 200E.
A5: ELF 200E
A6: ELF 300E.
A7: ELF 300E
A8: ELF 300H.
A9: ELF 300H
A10: ELF 350F
A11: ELF 350H
A12: ELF 350K
A13: ELF 400F.
A14: ELF 400F
... A44: FORWARD 1400Q
