Workbook

Sheet Cubicaje y Peso
AG1: .
C2: Medidas en Exterior - Centímetros - Máximas | G2: Medidas para Carga en Interior - Centímetros - Máximas | K2: Medidas del Producto y Peso Unitario (Frente a la Capacidad de Carga Máxima) | R2: Medidas para Carga en Exterior - Centímetros - Idóneas | V2: Medidas para Carga en Interior - Centímetros - Idóneas | Z2: Medidas del Producto y Peso Unitario (Frente a la Capacidad de Carga Idónea)
B3: Modelo | C3: Largo | D3: Ancho | E3: Alto | G3: Largo | H3: Ancho | I3: Alto | K3: Largo | L3: Ancho | M3: Alto | N3: Kg por C/U | O3: Habilitados | P3: Peso Total | R3: Largo | S3: Ancho | T3: Alto | V3: Largo | W3: Ancho | X3: Alto | Z3: Largo | AA3: Ancho | AB3: Alto | AC3: Kg por C/U | AD3: Habilitados | AE3: Peso Total
B4: ELF 100E | C4: 350 | D4: 190 | O4: =(($G4*$H4*$I4))/(($K4*$L4*$M4)) -> #DIV/0! | P4: =$N4*$O4 -> #DIV/0! | R4: 330 | S4: 200 | T4: 200 | V4: 315 | W4: 190 | X4: 180 | AD4: =(($V4*$W4*$X4))/(($Z4*$AA4*$AB4)) -> #DIV/0! | AE4: =$AC4*$AD4 -> #DIV/0!
B5: ELF 200E | C5: 350 | D5: 190 | O5: =(($G5*$H5*$I5))/(($K5*$L5*$M5)) -> #DIV/0! | P5: =$N5*$O5 -> #DIV/0! | R5: 330 | S5: 200 | T5: 200 | V5: 315 | W5: 190 | X5: 180 | AD5: =(($V5*$W5*$X5))/(($Z5*$AA5*$AB5)) -> #DIV/0! | AE5: =$AC5*$AD5 -> #DIV/0!
B6: ELF 300E | C6: 350 | D6: 200 | O6: =(($G6*$H6*$I6))/(($K6*$L6*$M6)) -> #DIV/0! | P6: =$N6*$O6 -> #DIV/0! | R6: 330 | S6: 200 | T6: 200 | V6: 315 | W6: 190 | X6: 180 | AD6: =(($V6*$W6*$X6))/(($Z6*$AA6*$AB6)) -> #DIV/0! | AE6: =$AC6*$AD6 -> #DIV/0!
B7: ELF 300H | C7: 450 | D7: 200 | O7: =(($G7*$H7*$I7))/(($K7*$L7*$M7)) -> #DIV/0! | P7: =$N7*$O7 -> #DIV/0! | R7: 450 | S7: 200 | T7: 200 | V7: 430 | W7: 190 | X7: 180 | AD7: =(($V7*$W7*$X7))/(($Z7*$AA7*$AB7)) -> #DIV/0! | AE7: =$AC7*$AD7 -> #DIV/0!
B8: ELF 400F | C8: 380 | D8: 240 | O8: =(($G8*$H8*$I8))/(($K8*$L8*$M8)) -> #DIV/0! | P8: =$N8*$O8 -> #DIV/0! | R8: 380 | S8: 240 | T8: 230 | V8: 360 | W8: 230 | X8: 210 | AD8: =(($V8*$W8*$X8))/(($Z8*$AA8*$AB8)) -> #DIV/0! | AE8: =$AC8*$AD8 -> #DIV/0!
B9: ELF 400H | C9: 440 | D9: 240 | O9: =(($G9*$H9*$I9))/(($K9*$L9*$M9)) -> #DIV/0! | P9: =$N9*$O9 -> #DIV/0! | R9: 460 | S9: 240 | T9: 230 | V9: 440 | W9: 230 | X9: 210 | AD9: =(($V9*$W9*$X9))/(($Z9*$AA9*$AB9)) -> #DIV/0! | AE9: =$AC9*$AD9 -> #DIV/0!
B10: ELF 400K | C10: 480 | D10: 240 | O10: =(($G10*$H10*$I10))/(($K10*$L10*$M10)) -> #DIV/0! | P10: =$N10*$O10 -> #DIV/0! | R10: 500 | S10: 240 | T10: 230 | V10: 480 | W10: 230 | X10: 210 | AD10: =(($V10*$W10*$X10))/(($Z10*$AA10*$AB10)) -> #DIV/0! | AE10: =$AC10*$AD10 -> #DIV/0!
B11: ELF 500F | C11: 380 | D11: 240 | O11: =(($G11*$H11*$I11))/(($K11*$L11*$M11)) -> #DIV/0! | P11: =$N11*$O11 -> #DIV/0! | R11: 380 | S11: 240 | T11: 230 | V11: 360 | W11: 230 | X11: 210 | AD11: =(($V11*$W11*$X11))/(($Z11*$AA11*$AB11)) -> #DIV/0! | AE11: =$AC11*$AD11 -> #DIV/0!
B12: ELF 500H | C12: 457.2 | D12: 240 | O12: =(($G12*$H12*$I12))/(($K12*$L12*$M12)) -> #DIV/0! | P12: =$N12*$O12 -> #DIV/0! | R12: 460 | S12: 240 | T12: 230 | V12: 440 | W12: 230 | X12: 210 | AD12: =(($V12*$W12*$X12))/(($Z12*$AA12*$AB12)) -> #DIV/0! | AE12: =$AC12*$AD12 -> #DIV/0!
B13: ELF 500K | C13: 548.6 | D13: 240 | O13: =(($G13*$H13*$I13))/(($K13*$L13*$M13)) -> #DIV/0! | P13: =$N13*$O13 -> #DIV/0! | R13: 500 | S13: 240 | T13: 230 | V13: 480 | W13: 230 | X13: 210 | AD13: =(($V13*$W13*$X13))/(($Z13*$AA13*$AB13)) -> #DIV/0! | AE13: =$AC13*$AD13 -> #DIV/0!
B14: ELF 500M | C14: 609.6 | D14: 240 | O14: =(($G14*$H14*$I14))/(($K14*$L14*$M14)) -> #DIV/0! | P14: =$N14*$O14 -> #DIV/0! | R14: 600 | S14: 240 | T14: 230 | V14: 580 | W14: 230 | X14: 210 | AD14: =(($V14*$W14*$X14))/(($Z14*$AA14*$AB14)) -> #DIV/0! | AE14: =$AC14*$AD14 -> #DIV/0!
B15: ELF 600H | C15: 457.2 | D15: 240 | O15: =(($G15*$H15*$I15))/(($K15*$L15*$M15)) -> #DIV/0! | P15: =$N15*$O15 -> #DIV/0! | R15: 480 | S15: 240 | T15: 230 | V15: 440 | W15: 230 | X15: 210 | AD15: =(($V15*$W15*$X15))/(($Z15*$AA15*$AB15)) -> #DIV/0! | AE15: =$AC15*$AD15 -> #DIV/0!
... B22: Forward 1400K | C22: 550 | D22: 250 | O22: =(($G22*$H22*$I22))/(($K22*$L22*$M22)) -> #DIV/0! | P22: =$N22*$O22 -> #DIV/0! | R22: 620 | S22: 260 | T22: 250 | V22: 600 | W22: 250 | X22: 230 | AD22: =(($V22*$W22*$X22))/(($Z22*$AA22*$AB22)) -> #DIV/0! | AE22: =$AC22*$AD22 -> #DIV/0!
B23: Forward 1400Q | C23: 800 | D23: 250 | E23: 250 | O23: =(($G23*$H23*$I23))/(($K23*$L23*$M23)) -> #DIV/0! | P23: =$N23*$O23 -> #DIV/0! | R23: 750 | S23: 260 | T23: 250 | V23: 730 | W23: 250 | X23: 230 | AD23: =(($V23*$W23*$X23))/(($Z23*$AA23*$AB23)) -> #DIV/0! | AE23: =$AC23*$AD23 -> #DIV/0!

Sheet Distribución de Carga
C2: Medidas de las Undades - Centímetros - Según Ficha Técnica | G2: Distribución de la Carga entre la Distancia de los Ejes Según:
B3: Modelo | C3: CA | D3: BOC | E3: CE | G3: F. Técnica | H3: Real o Carrocero
B4: ELF 100E | C4: 202.2 | D4: 22.1 | E4: 316.7 | G4: =$C4/($E4-$D4) -> 0.68635438 | H4: =$C4/('Cubicaje y Peso'!$R4-$D4) -> 0.65670672
B5: ELF 200E | C5: 202.7 | D5: 22.1 | E5: 317.2 | G5: =$C5/($E5-$D5) -> 0.6868858 | H5: =$C5/('Cubicaje y Peso'!$R5-$D5) -> 0.65833063
B6: ELF 300E | C6: 202.2 | D6: 22.1 | E6: 316.2 | G6: =$C6/($E6-$D6) -> 0.68752125 | H6: =$C6/('Cubicaje y Peso'!$R6-$D6) -> 0.65670672
B7: ELF 300H | C7: 289.2 | D7: 22.1 | E7: 445.7 | G7: =$C7/($E7-$D7) -> 0.68271955 | H7: =$C7/('Cubicaje y Peso'!$R7-$D7) -> 0.67585885
B8: ELF 400F | C8: 219.2 | D8: 16.6 | E8: 329.2 | G8: =$C8/($E8-$D8) -> 0.70121561 | H8: =$C8/('Cubicaje y Peso'!$R8-$D8) -> 0.60319207
B9: ELF 400H | C9: 279.2 | D9: 16.6 | E9: 389.2 | G9: =$C9/($E9-$D9) -> 0.74932904 | H9: =$C9/('Cubicaje y Peso'!$R9-$D9) -> 0.62967975
B10: ELF 400K | C10: 324.2 | D10: 16.6 | E10: 434.2 | G10: =$C10/($E10-$D10) -> 0.776341 | H10: =$C10/('Cubicaje y Peso'!$R10-$D10) -> 0.67066612
B11: ELF 500F | C11: 219.2 | D11: 16.6 | E11: 329.2 | G11: =$C11/($E11-$D11) -> 0.70121561 | H11: =$C11/('Cubicaje y Peso'!$R11-$D11) -> 0.60319207
B12: ELF 500H | C12: 279.2 | D12: 16.6 | E12: 389.2 | G12: =$C12/($E12-$D12) -> 0.74932904 | H12: =$C12/('Cubicaje y Peso'!$R12-$D12) -> 0.62967975
B13: ELF 500K | C13: 324.2 | D13: 16.6 | E13: 434.2 | G13: =$C13/($E13-$D13) -> 0.776341 | H13: =$C13/('Cubicaje y Peso'!$R13-$D13) -> 0.67066612
B14: ELF 500M | C14: 390.2 | D14: 16.6 | E14: 500.2 | G14: =$C14/($E14-$D14) -> 0.80686518 | H14: =$C14/('Cubicaje y Peso'!$R14-$D14) -> 0.66883785
B15: ELF 600H | C15: 279.2 | D15: 16.6 | E15: 389.2 | G15: =$C15/($E15-$D15) -> 0.74932904 | H15: =$C15/('Cubicaje y Peso'!$R15-$D15) -> 0.60250324
... B23: Forward 1400Q | C23: 492.4 | D23: 10.7 | E23: 718.9 | G23: =$C23/($E23-$D23) -> 0.69528382 | H23: =$C23/('Cubicaje y Peso'!$R23-$D23) -> 0.66603544

Sheet Distancia y Consumo
C2: Capacidad del Tanque de Combustible | D2: Rendimiento Mínimo Km por Litro | E2: Rendimiento Promedio Km por Litro | F2: Rendimiento Máximo Km por Litro | G2: Distancia Mínima Recorrida con Tanque Lleno | H2: Distancia Promedio Recorrida con Tanque Lleno | I2: Distancia Máxima Recorrida con Tanque Lleno | J2: Caballos de Fuerza | K2: Torque | L2: Relación de la 1° Velocidad | M2: Relación del Diferencial | N2: Torque Final Entregado | O2: Número de Cilindros y Litros | P2: Tipos de Frenos & Tamaño de RIN
B3: Modelo | C3: Litros | D3: Kilómetros | E3: =$D$3 -> Kilómetros | F3: =$D$3 -> Kilómetros | G3: Total Mínimo en Km | H3: Total Promedio en Km | I3: Total Máximo en Km | J3: HP | K3: Lb/pie | L3: Torque de la 1° | M3: Por el Diferencial | N3: Lb/pie * Transmisión * Diferencial | O3: Tamaño de Motor | P3: Delantero/Trasero - Tipo de Freno - RIN
B4: ELF 100E | C4: 75 | D4: 9 | E4: 10 | F4: 11 | G4: =$C4*$D4 -> 675 | H4: =$C4*$E4 -> 750 | I4: =$C4*$F4 -> 825 | J4: 122 | K4: 262 | L4: 5.315 | M4: 4.777 | N4: =$K4*$L4*$M4 -> 6652.1158 | O4: 4C en L 3 Litros | P4: Tambor/Tambor - Hidráulico - R16
B5: ELF 200E | C5: 75 | D5: 8.5 | E5: 9 | F5: 9.5 | G5: =$C5*$D5 -> 637.5 | H5: =$C5*$E5 -> 675 | I5: =$C5*$F5 -> 712.5 | J5: =$J$4 -> 122 | K5: =$K$4 -> 262 | L5: =$L$4 -> 5.315 | M5: 5.375 | N5: =$K5*$L5*$M5 -> 7484.8488 | O5: =$O$4 -> 4C en L 3 Litros | P5: Disco/Tambor - Hidráulico - R16
B6: ELF 300E | C6: 75 | D6: 7.5 | E6: 8 | F6: 8.5 | G6: =$C6*$D6 -> 562.5 | H6: =$C6*$E6 -> 600 | I6: =$C6*$F6 -> 637.5 | J6: =$J$4 -> 122 | K6: =$K$4 -> 262 | L6: =$L$4 -> 5.315 | M6: =$M$5 -> 5.375 | N6: =$K6*$L6*$M6 -> 7484.8488 | O6: =$O$4 -> 4C en L 3 Litros | P6: =$P$5 -> Disco/Tambor - Hidráulico - R16
B7: ELF 300H | C7: 100 | D7: =$D$6 -> 7.5 | E7: =$E$6 -> 8 | F7: =$F$6 -> 8.5 | G7: =$C7*$D7 -> 750 | H7: =$C7*$E7 -> 800 | I7: =$C7*$F7 -> 850 | J7: =$J$4 -> 122 | K7: =$K$4 -> 262 | L7: =$L$4 -> 5.315 | M7: =$M$5 -> 5.375 | N7: =$K7*$L7*$M7 -> 7484.8488 | O7: =$O$4 -> 4C en L 3 Litros | P7: =$P$5 -> Disco/Tambor - Hidráulico - R16
B8: ELF 400F | C8: 140 | D8: 6.5 | E8: 7 | F8: 7.5 | G8: =$C8*$D8 -> 910 | H8: =$C8*$E8 -> 980 | I8: =$C8*$F8 -> 1050 | J8: 172 | K8: 376 | L8: 6.369 | M8: 4.3 | N8: =$K8*$L8*$M8 -> 10297.399 | O8: 4C en L 5.2 Litros | P8: =$P$5 -> Disco/Tambor - Hidráulico - R16
B9: ELF 400H | C9: 140 | D9: =$D$8 -> 6.5 | E9: =$E$8 -> 7 | F9: =$F$8 -> 7.5 | G9: =$C9*$D9 -> 910 | H9: =$C9*$E9 -> 980 | I9: =$C9*$F9 -> 1050 | J9: =$J$8 -> 172 | K9: =$K$8 -> 376 | L9: =$L$8 -> 6.369 | M9: =$M$8 -> 4.3 | N9: =$K9*$L9*$M9 -> 10297.399 | O9: =$O$8 -> 4C en L 5.2 Litros | P9: =$P$5 -> Disco/Tambor - Hidráulico - R16
B10: ELF 400K | C10: 140 | D10: =$D$8 -> 6.5 | E10: =$E$8 -> 7 | F10: =$F$8 -> 7.5 | G10: =$C10*$D10 -> 910 | H10: =$C10*$E10 -> 980 | I10: =$C10*$F10 -> 1050 | J10: =$J$8 -> 172 | K10: =$K$8 -> 376 | L10: =$L$8 -> 6.369 | M10: =$M$8 -> 4.3 | N10: =$K10*$L10*$M10 -> 10297.399 | O10: =$O$8 -> 4C en L 5.2 Litros | P10: =$P$5 -> Disco/Tambor - Hidráulico - R16
B11: ELF 500F | C11: 140 | D11: 5.5 | E11: 6 | F11: 6.5 | G11: =$C11*$D11 -> 770 | H11: =$C11*$E11 -> 840 | I11: =$C11*$F11 -> 910 | J11: =$J$8 -> 172 | K11: =$K$8 -> 376 | L11: =$L$8 -> 6.369 | M11: 4.556 | N11: =$K11*$L11*$M11 -> 10910.454 | O11: =$O$8 -> 4C en L 5.2 Litros | P11: Disco/Tambor - Booster Hidráulico - R19.5
B12: ELF 500H | C12: 140 | D12: =$D$11 -> 5.5 | E12: =$E$11 -> 6 | F12: =$F$11 -> 6.5 | G12: =$C12*$D12 -> 770 | H12: =$C12*$E12 -> 840 | I12: =$C12*$F12 -> 910 | J12: =$J$8 -> 172 | K12: =$K$8 -> 376 | L12: =$L$8 -> 6.369 | M12: =$M$11 -> 4.556 | N12: =$K12*$L12*$M12 -> 10910.454 | O12: =$O$8 -> 4C en L 5.2 Litros | P12: =$P$11 -> Disco/Tambor - Booster Hidráulico - R19.5
B13: ELF 500K | C13: 140 | D13: =$D$11 -> 5.5 | E13: =$E$11 -> 6 | F13: =$F$11 -> 6.5 | G13: =$C13*$D13 -> 770 | H13: =$C13*$E13 -> 840 | I13: =$C13*$F13 -> 910 | J13: =$J$8 -> 172 | K13: =$K$8 -> 376 | L13: =$L$8 -> 6.369 | M13: =$M$11 -> 4.556 | N13: =$K13*$L13*$M13 -> 10910.454 | O13: =$O$8 -> 4C en L 5.2 Litros | P13: =$P$11 -> Disco/Tambor - Booster Hidráulico - R19.5
B14: ELF 500M | C14: 140 | D14: =$D$11 -> 5.5 | E14: =$E$11 -> 6 | F14: =$F$11 -> 6.5 | G14: =$C14*$D14 -> 770 | H14: =$C14*$E14 -> 840 | I14: =$C14*$F14 -> 910 | J14: =$J$8 -> 172 | K14: =$K$8 -> 376 | L14: =$L$8 -> 6.369 | M14: =$M$11 -> 4.556 | N14: =$K14*$L14*$M14 -> 10910.454 | O14: =$O$8 -> 4C en L 5.2 Litros | P14: =$P$11 -> Disco/Tambor - Booster Hidráulico - R19.5
B15: ELF 600H | C15: 140 | D15: 5 | E15: 5.5 | F15: 6 | G15: =$C15*$D15 -> 700 | H15: =$C15*$E15 -> 770 | I15: =$C15*$F15 -> 840 | J15: =$J$8 -> 172 | K15: =$K$8 -> 376 | L15: =$L$8 -> 6.369 | M15: =$M$11 -> 4.556 | N15: =$K15*$L15*$M15 -> 10910.454 | O15: =$O$8 -> 4C en L 5.2 Litros | P15: =$P$11 -> Disco/Tambor - Booster Hidráulico - R19.5
B16: ELF 600K | C16: 140 | D16: =$D$15 -> 5 | E16: =$E$15 -> 5.5 | F16: =$F$15 -> 6 | G16: =$C16*$D16 -> 700 | H16: =$C16*$E16 -> 770 | I16: =$C16*$F16 -> 840 | J16: =$J$8 -> 172 | K16: =$K$8 -> 376 | L16: =$L$8 -> 6.369 | M16: =$M$11 -> 4.556 | N16: =$K16*$L16*$M16 -> 10910.454 | O16: =$O$8 -> 4C en L 5.2 Litros | P16: =$P$11 -> Disco/Tambor - Booster Hidráulico - R19.5
B17: ELF 600M | C17: 140 | D17: =$D$15 -> 5 | E17: =$E$15 -> 5.5 | F17: =$F$15 -> 6 | G17: =$C17*$D17 -> 700 | H17: =$C17*$E17 -> 770 | I17: =$C17*$F17 -> 840 | J17: =$J$8 -> 172 | K17: =$K$8 -> 376 | L17: =$L$8 -> 6.369 | M17: =$M$11 -> 4.556 | N17: =$K17*$L17*$M17 -> 10910.454 | O17: =$O$8 -> 4C en L 5.2 Litros | P17: =$P$11 -> Disco/Tambor - Booster Hidráulico - R19.5
B18: Forward 800K | C18: 200 | D18: 4.5 | E18: 5 | F18: 5.5 | G18: =$C18*$D18 -> 900 | H18: =$C18*$E18 -> 1000 | I18: =$C18*$F18 -> 1100 | J18: 237 | K18: 520 | L18: 6.615 | M18: 4.1 | N18: =$K18*$L18*$M18 -> 14103.18 | O18: 6C en L 7.8 Litros | P18: Tambor/Tambor - Aire Sobre Hidráulico - R19.5
B19: Forward 800M | C19: 200 | D19: =$D$18 -> 4.5 | E19: =$E$18 -> 5 | F19: =$F$18 -> 5.5 | G19: =$C19*$D19 -> 900 | H19: =$C19*$E19 -> 1000 | I19: =$C19*$F19 -> 1100 | J19: =$J$18 -> 237 | K19: =$K$18 -> 520 | L19: =$L$18 -> 6.615 | M19: =$M$18 -> 4.1 | N19: =$K19*$L19*$M19 -> 14103.18 | O19: =$O$18 -> 6C en L 7.8 Litros | P19: =$P$18 -> Tambor/Tambor - Aire Sobre Hidráulico - R19.5
B20: Forward 1100L | C20: 200 | D20: 4 | E20: 4.5 | F20: 5 | G20: =$C20*$D20 -> 800 | H20: =$C20*$E20 -> 900 | I20: =$C20*$F20 -> 1000 | J20: =$J$18 -> 237 | K20: =$K$18 -> 520 | L20: =$L$18 -> 6.615 | M20: 6.143 | N20: =$K20*$L20*$M20 -> 21130.691 | O20: =$O$18 -> 6C en L 7.8 Litros | P20: Tambor/Tambor - Frenos de Aire - R22.5
B21: Forward 1100Q | C21: 200 | D21: =$D$20 -> 4 | E21: =$E$20 -> 4.5 | F21: =$F$20 -> 5 | G21: =$C21*$D21 -> 800 | H21: =$C21*$E21 -> 900 | I21: =$C21*$F21 -> 1000 | J21: =$J$18 -> 237 | K21: =$K$18 -> 520 | L21: =$L$18 -> 6.615 | M21: =$M$20 -> 6.143 | N21: =$K21*$L21*$M21 -> 21130.691 | O21: =$O$18 -> 6C en L 7.8 Litros | P21: =$P$20 -> Tambor/Tambor - Frenos de Aire - R22.5
B22: Forward 1400K | C22: 200 | D22: 4 | E22: 4.5 | F22: 5 | G22: =$C22*$D22 -> 800 | H22: =$C22*$E22 -> 900 | I22: =$C22*$F22 -> 1000 | J22: =$J$18 -> 237 | K22: =$K$18 -> 520 | L22: 9.479 | M22: 6.429 | N22: =$K22*$L22*$M22 -> 31689.055 | O22: =$O$18 -> 6C en L 7.8 Litros | P22: =$P$20 -> Tambor/Tambor - Frenos de Aire - R22.5
B23: Forward 1400Q | C23: 400 | D23: =$D$22 -> 4 | E23: =$E$22 -> 4.5 | F23: =$F$22 -> 5 | G23: =$C23*$D23 -> 1600 | H23: =$C23*$E23 -> 1800 | I23: =$C23*$F23 -> 2000 | J23: =$J$18 -> 237 | K23: =$K$18 -> 520 | L23: =$L$22 -> 9.479 | M23: =$M$22 -> 6.429 | N23: =$K23*$L23*$M23 -> 31689.055 | O23: =$O$18 -> 6C en L 7.8 Litros | P23: =$P$20 -> Tambor/Tambor - Frenos de Aire - R22.5

Sheet Hoja1
B2: Modelo | C2: Distancia Entre Ejes | D2: BBC | E2: BA | F2: Centro Eje & Cabina | G2: BOC | I2: CE | K2: Volado trasero
B3: ELF 100E | C3: 2.475 | D3: 1.553 | E3: 1.11 | F3: =$D3-$E3 -> 0.443 | G3: 0.221 | H3: =$G3+$F3 -> 0.664 | I3: 3.167 | K3: =$C3*0.3333 -> 0.8249175
B4: ELF 100E. | C4: 2.475 | D4: 1.563 | F4: =$D4-$E4 -> 1.563 | G4: 0.111 | H4: =$G4+$F4 -> 1.674 | K4: =$C4*0.3333 -> 0.8249175
B5: ELF 200E | C5: 2.49 | F5: =$D5-$E5 -> 0 | H5: =$G5+$F5 -> 0 | K5: =$C5*0.3333 -> 0.829917
B6: ELF 200E. | C6: 2.47 | F6: =$D6-$E6 -> 0 | G6: 0.111 | H6: =$G6+$F6 -> 0.111 | K6: =$C6*0.3333 -> 0.823251
B7: ELF 300E | C7: 2.47 | F7: =$D7-$E7 -> 0 | H7: =$G7+$F7 -> 0 | K7: =$C7*0.3333 -> 0.823251
B8: ELF 300E. | C8: 2.47 | F8: =$D8-$E8 -> 0 | G8: 0.111 | H8: =$G8+$F8 -> 0.111 | K8: =$C8*0.3333 -> 0.823251
B9: ELF 300H | C9: 3.34 | F9: =$D9-$E9 -> 0 | H9: =$G9+$F9 -> 0 | K9: =$C9*0.3333 -> 1.113222
B10: ELF 300H. | C10: 3.34 | F10: =$D10-$E10 -> 0 | G10: 0.111 | H10: =$G10+$F10 -> 0.111 | K10: =$C10*0.3333 -> 1.113222
B11: ELF 350F. | C11: 2.76 | F11: =$D11-$E11 -> 0 | G11: 0.111 | H11: =$G11+$F11 -> 0.111 | K11: =$C11*0.3333 -> 0.919908
B12: ELF 350H. | C12: 3.36 | F12: =$D12-$E12 -> 0 | G12: 0.111 | H12: =$G12+$F12 -> 0.111 | K12: =$C12*0.3333 -> 1.119888
B13: ELF 350K. | C13: 3.81 | F13: =$D13-$E13 -> 0 | G13: 0.111 | H13: =$G13+$F13 -> 0.111 | K13: =$C13*0.3333 -> 1.269873
B14: ELF 400F | C14: 2.76 | F14: =$D14-$E14 -> 0 | H14: =$G14+$F14 -> 0 | K14: =$C14*0.3333 -> 0.919908
B15: ELF 400F. | C15: 2.76 | F15: =$D15-$E15 -> 0 | G15: 0.111 | H15: =$G15+$F15 -> 0.111 | K15: =$C15*0.3333 -> 0.919908
B16: ELF 400H | C16: 3.36 | F16: =$D16-$E16 -> 0 | H16: =$G16+$F16 -> 0 | K16: =$C16*0.3333 -> 1.119888
B17: ELF 400H. | C17: 3.36 | F17: =$D17-$E17 -> 0 | G17: 0.111 | H17: =$G17+$F17 -> 0.111 | K17: =$C17*0.3333 -> 1.119888
B18: ELF 400K | C18: 3.8 | F18: =$D18-$E18 -> 0 | H18: =$G18+$F18 -> 0 | K18: =$C18*0.3333 -> 1.26654
B19: ELF 400K. | C19: 3.8 | F19: =$D19-$E19 -> 0 | G19: 0.111 | H19: =$G19+$F19 -> 0.111 | K19: =$C19*0.3333 -> 1.26654
B20: ELF 500F | C20: 2.76 | F20: =$D20-$E20 -> 0 | H20: =$G20+$F20 -> 0 | K20: =$C20*0.3333 -> 0.919908
B21: ELF 500F. | C21: 2.76 | F21: =$D21-$E21 -> 0 | G21: 0.111 | H21: =$G21+$F21 -> 0.111 | K21: =$C21*0.3333 -> 0.919908
B22: ELF 500H | C22: 3.36 | F22: =$D22-$E22 -> 0 | H22: =$G22+$F22 -> 0 | K22: =$C22*0.3333 -> 1.119888
B23: ELF 500H. | C23: 3.36 | F23: =$D23-$E23 -> 0 | G23: 0.111 | H23: =$G23+$F23 -> 0.111 | K23: =$C23*0.3333 -> 1.119888
B24: ELF 500K | C24: 3.8 | F24: =$D24-$E24 -> 0 | H24: =$G24+$F24 -> 0 | K24: =$C24*0.3333 -> 1.26654
B25: ELF 500K. | C25: 3.8 | F25: =$D25-$E25 -> 0 | G25: 0.111 | H25: =$G25+$F25 -> 0.111 | K25: =$C25*0.3333 -> 1.26654
B26: ELF 500M+ | C26: 4.47 | F26: =$D26-$E26 -> 0 | H26: =$G26+$F26 -> 0 | K26: =$C26*0.3333 -> 1.489851
B27: ELF 500M+. | C27: 4.47 | F27: =$D27-$E27 -> 0 | G27: 0.111 | H27: =$G27+$F27 -> 0.111 | K27: =$C27*0.3333 -> 1.489851
B28: ELF 600H | C28: 3.36 | F28: =$D28-$E28 -> 0 | H28: =$G28+$F28 -> 0 | K28: =$C28*0.3333 -> 1.119888
B29: ELF 600H. | C29: 3.36 | F29: =$D29-$E29 -> 0 | G29: 0.111 | H29: =$G29+$F29 -> 0.111 | K29: =$C29*0.3333 -> 1.119888
B30: ELF 600K | C30: 3.8 | F30: =$D30-$E30 -> 0 | H30: =$G30+$F30 -> 0 | K30: =$C30*0.3333 -> 1.26654
B31: ELF 600K. | C31: 3.8 | F31: =$D31-$E31 -> 0 | G31: 0.111 | H31: =$G31+$F31 -> 0.111 | K31: =$C31*0.3333 -> 1.26654
B32: ELF 600M+ | C32: 4.47 | F32: =$D32-$E32 -> 0 | H32: =$G32+$F32 -> 0 | K32: =$C32*0.3333 -> 1.489851
B33: ELF 600M+. | C33: 4.47 | F33: =$D33-$E33 -> 0 | G33: 0.111 | H33: =$G33+$F33 -> 0.111 | K33: =$C33*0.3333 -> 1.489851
B34: FORWARD 800K | C34: 4.36 | F34: =$D34-$E34 -> 0 | H34: =$G34+$F34 -> 0 | K34: =$C34*0.3333 -> 1.453188
B35: FORWARD 800K. | C35: 4.06 | F35: =$D35-$E35 -> 0 | G35: 0.111 | H35: =$G35+$F35 -> 0.111 | K35: =$C35*0.3333 -> 1.353198
B36: FORWARD 800M | C36: 4.86 | F36: =$D36-$E36 -> 0 | H36: =$G36+$F36 -> 0 | K36: =$C36*0.3333 -> 1.619838
B37: FORWARD 800M. | C37: 4.66 | F37: =$D37-$E37 -> 0 | G37: 0.111 | H37: =$G37+$F37 -> 0.111 | K37: =$C37*0.3333 -> 1.553178
B38: FORWARD 1100L | C38: 4.25 | F38: =$D38-$E38 -> 0 | H38: =$G38+$F38 -> 0 | K38: =$C38*0.3333 -> 1.416525
B39: FORWARD 1100M. | C39: 4.65 | F39: =$D39-$E39 -> 0 | G39: 0.111 | H39: =$G39+$F39 -> 0.111 | K39: =$C39*0.3333 -> 1.549845
B40: FORWARD 1100Q | C40: 5.55 | F40: =$D40-$E40 -> 0 | H40: =$G40+$F40 -> 0 | K40: =$C40*0.3333 -> 1.849815
B41: FORWARD 1100Q. | C41: 5.55 | F41: =$D41-$E41 -> 0 | G41: 0.111 | H41: =$G41+$F41 -> 0.111 | K41: =$C41*0.3333 -> 1.849815
...
